Workbook
Name multiply: 'BUDGET COMMERCIALE'!#REF!
Name p: 'BUDGET COMMERCIALE'!#REF!

Sheet BUDGET COMMERCIALE
B1: Budget del settore distributivo - SETTORE CALZATURIERO
A2: PIANO DEI VOLUMI DI VENDITA | Z2: Tabella delle informazioni commerciali
A3: LUREX 1 | B3: GEN. | C3: FEB. | D3: MAR. | E3: I TRIM | F3: APR. | G3: MAG. | H3: GIU. | I3: II TRIM | J3: LUG. | K3: AGO | L3: SET | M3: III TRIM | N3: OTT. | O3: NOV. | P3: DIC. | Q3: IV TRIM. | R3: TOTALE | V3: LUREX | X3: prodotti | Y3: Italia | AA3: Francia
A4: Italia | V4: Sconti | Y4: I semestre | Z4: II semestre | AA4: I semestre | AB4: II semestre
A5: Moccassino | B5: 6000 | C5: 5500 | D5: 6000 | E5: =B5+C5+D5 -> 17500 | F5: 6000 | G5: 6500 | H5: 7000 | I5: =SUM(F5:H5) -> 19500 | J5: 6800 | K5: 6350 | L5: 6200 | M5: =SUM(J5:L5) -> 19350 | N5: 5860 | O5: 5420 | P5: 5000 | Q5: =SUM(N5:P5) -> 16280 | R5: =Q5+M5+I5+E5 -> 72630 | V5: Mocassino | Y5: 0.02 | Z5: 0.02 | AA5: 0.03 | AB5: 0.03
A6: Decollete' | B6: 6000 | C6: 5500 | D6: 6000 | E6: =B6+C6+D6 -> 17500 | F6: 5800 | G6: 6100 | H6: 6730 | I6: =SUM(F6:H6) -> 18630 | J6: 6560 | K6: 6100 | L6: 5960 | M6: 18620 | N6: 6000 | O6: 5740 | P6: 5380 | Q6: =SUM(N6:P6) -> 17120 | R6: =Q6+M6+I6+E6 -> 71870 | V6: Decollete' | Y6: 0.03 | Z6: 0.03 | AA6: 0.05 | AB6: 0.05
A7: All star | B7: 2000 | C7: 2000 | D7: 2500 | E7: =B7+C7+D7 -> 6500 | F7: 3350 | G7: 3860 | H7: 4100 | I7: =SUM(F7:H7) -> 11310 | J7: 3900 | K7: 4050 | L7: 3800 | M7: 11750 | N7: 3150 | O7: 2890 | P7: 2120 | Q7: =SUM(N7:P7) -> 8160 | R7: =Q7+M7+I7+E7 -> 37720 | V7: All star | Y7: 0.04 | Z7: 0.04
A8: Slip on in pelle | B8: 640 | C8: 640 | D8: 780 | E8: =SUM(B8:D8) -> 2060 | F8: 1060 | G8: 1240 | H8: 1320 | I8: =SUM(F8:H8) -> 3620 | J8: 1240 | K8: 1280 | L8: 1200 | M8: =SUM(J8:L8) -> 3720 | N8: 1000 | O8: 920 | P8: 1000 | Q8: =SUM(N8:P8) -> 2920 | R8: =Q8+M8+I8+E8 -> 12320 | V8: Slip on in pelle | Y8: 0.03 | Z8: 0.03
A9: Francia
A10: Moccassino | B10: 3800 | C10: 4000 | D10: 4400 | E10: =B10+C10+D10 -> 12200 | F10: 4750 | G10: 5200 | H10: 5430 | I10: =SUM(F10:H10) -> 15380 | J10: 5860 | K10: 5780 | L10: 5420 | M10: 17060 | N10: 4980 | O10: 4310 | P10: 3860 | Q10: 13150 | R10: =Q10+M10+I10+E10 -> 57790
A11: Decollete' | B11: 1300 | C11: 1400 | D11: 1800 | E11: =B11+C11+D11 -> 4500 | F11: 1970 | G11: 2350 | H11: 2560 | I11: =SUM(F11:H11) -> 6880 | J11: 2890 | K11: 3000 | L11: 2640 | M11: 8530 | N11: 2210 | O11: 1900 | P11: 1560 | Q11: 5670 | R11: =Q11+M11+I11+E11 -> 25580
V12: Costi unitari trasporto | X12: Mocassino | Y12: 0.3 | Z12: 0.35 | AA12: 0.5 | AB12: 0.55
X13: Decollete' | Y13: 0.3 | Z13: 0.35 | AA13: 0.5 | AB13: 0.55
X14: All star | Y14: 0.3 | Z14: 0.35
A15: PREZZI DI VENDITA | X15: Slip on in pelle | Y15: 0.3 | Z15: 0.3
A16: LUREX | B16: Italia | D16: Estero
B17: I semestre | C17: II semestre | D17: I semestre | E17: II semestre
A18: Mocassino | B18: 40 | C18: 40 | D18: 40 | E18: 40
A19: Decollete' | B19: 50 | C19: 50 | D19: 50 | E19: 50 | V19: provvigioni esterne | X19: Mocassino | Y19: 0.02 | Z19: 0.02 | AA19: 0.03 | AB19: 0.03
A20: All star | B20: 30 | C20: 30 | X20: Decollete' | Y20: 0.02 | Z20: 0.02 | AA20: 0.03 | AB20: 0.03
A21: Slip on in pelle | B21: 40 | C21: 40 | X21: All star | Y21: 0.02 | Z21: 0.02
X22: slip on in pelle | Y22: 0.02 | Z22: 0.02
A24: BUDGET DEI RICAVI TEORICI
A25: LUREX 1 | B25: GEN. | C25: FEB. | D25: MAR. | E25: I TRIM | F25: APR. | G25: MAG. | H25: GIU. | I25: II TRIM | J25: LUG. | K25: AGO | L25: SET | M25: III TRIM | N25: OTT. | O25: NOV. | P25: DIC. | Q25: IV TRIM. | R25: TOTALE
A26: Italia
A27: Moccassino | B27: =B5*B18 -> 240000 | C27: =C5*B18 -> 220000 | D27: =D5*B18 -> 240000 | E27: 700000 | F27: =F5*B18 -> 240000 | G27: =G5*B18 -> 260000 | H27: =H5*B18 -> 280000 | I27: =SUM(F27:H27) -> 780000 | J27: =J5*C18 -> 272000 | K27: =K5*C18 -> 254000 | L27: =L5*C18 -> 248000 | M27: =SUM(J27:L27) -> 774000 | N27: =N5*C18 -> 234400 | O27: =O5*C18 -> 216800 | P27: =P5*C18 -> 200000 | Q27: =SUM(N27:P27) -> 651200 | R27: =Q27+M27+I27+E27 -> 2905200
A28: Decollete' | B28: =B6*B19 -> 300000 | C28: =C6*B19 -> 275000 | D28: =D6*B19 -> 300000 | E28: 875000 | F28: =F6*B19 -> 290000 | G28: =G6*B19 -> 305000 | H28: =H6*B19 -> 336500 | I28: =SUM(F28:H28) -> 931500 | J28: =J6*C19 -> 328000 | K28: =K6*C19 -> 305000 | L28: =L6*C19 -> 298000 | M28: =SUM(J28:L28) -> 931000 | N28: =N6*C19 -> 300000 | O28: =SUM(O6*C19) -> 287000 | P28: =P6*C19 -> 269000 | Q28: =SUM(N28:P28) -> 856000 | R28: =Q28+M28+I28+E28 -> 3593500
A29: All star | B29: =B7*B20 -> 60000 | C29: =C7*B20 -> 60000 | D29: =D7*B20 -> 75000 | E29: 195000 | F29: =F7*B20 -> 100500 | G29: =G7*B20 -> 115800 | H29: =H7*B20 -> 123000 | I29: =SUM(F29:H29) -> 339300 | J29: =J7*C20 -> 117000 | K29: =K7*C20 -> 121500 | L29: =L7*C20 -> 114000 | M29: =SUM(J29:L29) -> 352500 | N29: =N7*C20 -> 94500 | O29: =O7*C20 -> 86700 | P29: =P7*C20 -> 63600 | Q29: =SUM(N29:P29) -> 244800 | R29: =Q29+M29+I29+E29 -> 1131600
A30: Slip on in pelle | B30: =B8*B21 -> 25600 | C30: =C8*B21 -> 25600 | D30: =D8*B21 -> 31200 | E30: =SUM(B30:D30) -> 82400 | F30: =F8*B21 -> 42400 | G30: =G8*B21 -> 49600 | H30: =H8*B21 -> 52800 | I30: =SUM(F30:H30) -> 144800 | J30: =J8*C21 -> 49600 | K30: =K8*C21 -> 51200 | L30: =L8*C21 -> 48000 | M30: =SUM(J30:L30) -> 148800 | N30: =N8*C21 -> 40000 | O30: =O8*C21 -> 36800 | P30: =P8*C21 -> 40000 | Q30: =SUM(N30:P30) -> 116800 | R30: =Q30+M30+I30+E30 -> 492800
A31: Totale | B31: =B27+B28+B29+B30 -> 625600 | C31: =C27+C28+C29+C30 -> 580600 | D31: =D27+D28+D29+D30 -> 646200 | E31: =E27+E28+E29+E30 -> 1852400 | F31: =SUM(F27:F30) -> 672900 | G31: =SUM(G27:G30) -> 730400 | H31: =SUM(H27:H30) -> 792300 | I31: =SUM(I27:I30) -> 2195600 | J31: =SUM(J27:J30) -> 766600 | K31: =SUM(K27:K30) -> 731700 | L31: =SUM(L27:L30) -> 708000 | M31: =SUM(M27:M30) -> 2206300 | ... Q31: =SUM(Q27:Q30) -> 1868800 | R31: =SUM(Q31+M31+I31+E31) -> 8123100
A32: Francia
A33: Moccassino | B33: =B10*D18 -> 152000 | C33: =C10*D18 -> 160000 | D33: =D10*D18 -> 176000 | E33: 488000 | F33: =F10*D18 -> 190000 | G33: =G10*D18 -> 208000 | H33: =H10*D18 -> 217200 | I33: =SUM(F32:H33) -> 615200 | J33: =J10*E18 -> 234400 | K33: =K10*E18 -> 231200 | L33: =L10*E18 -> 216800 | M33: 682400 | N33: =N10*E18 -> 199200 | O33: =O10*E18 -> 172400 | P33: =P10*E18 -> 154400 | Q33: 526000 | R33: =Q33+M33+I33+E33 -> 2311600
A34: Decollete' | B34: =B11*D19 -> 65000 | C34: =C11*D19 -> 70000 | D34: =D11*D19 -> 90000 | E34: 225000 | F34: =F11*D19 -> 98500 | G34: =G11*D19 -> 117500 | H34: =H11*D19 -> 128000 | I34: =SUM(F34:H34) -> 344000 | J34: =J11*E19 -> 144500 | K34: =K11*E19 -> 150000 | L34: =L11*E19 -> 132000 | M34: 426500 | N34: =N11*E19 -> 110500 | O34: =O11*E19 -> 95000 | P34: =P11*E19 -> 78000 | Q34: =SUM(N34:P34) -> 283500 | R34: =Q34+M34+I34+E34 -> 1279000
A35: Totale | B35: 217000 | C35: 230000 | D35: 266000 | E35: 713000 | F35: =SUM(F33:F34) -> 288500 | G35: =SUM(G33:G34) -> 325500 | H35: =SUM(H33:H34) -> 345200 | I35: =SUM(F35:H35) -> 959200 | J35: 378900 | K35: 381200 | L35: 348800 | M35: =L35+K35+J35 -> 1108900 | N35: =SUM(N33:N34) -> 309700 | O35: =SUM(O33:O34) -> 267400 | P35: =SUM(P33:P34) -> 232400 | Q35: =SUM(Q33:Q34) -> 809500 | R35: =Q35+M35+I35+E35 -> 3590600
A36: TOTALE | B36: =B31+B35 -> 842600 | C36: =C31+C35 -> 810600 | D36: =D31+D35 -> 912200 | E36: =E31+E35 -> 2565400 | F36: =F31+F35 -> 961400 | G36: =G31+G35 -> 1055900 | H36: =H31+H35 -> 1137500 | I36: =I31+I35 -> 3154800 | ... R36: =R31+R35 -> 11713700
A38: BUDGET DEGLI SCONTI
A39: LUREX 1 | B39: GEN. | C39: FEB. | D39: MAR. | E39: I TRIM | F39: APR. | G39: MAG. | H39: GIU. | I39: II TRIM | J39: LUG. | K39: AGO | L39: SET | M39: III TRIM | N39: OTT. | O39: NOV. | P39: DIC. | Q39: IV TRIM. | R39: TOTALE
A40: Italia
A41: Moccassino | B41: =B27*Y5 -> 4800 | C41: 4400 | D41: 4800 | E41: =B41+C41+D41 -> 14000 | F41: =F27*Y5 -> 4800 | G41: =G27*Y5 -> 5200 | H41: =H27*Y5 -> 5600 | I41: =SUM(F41:H41) -> 15600 | J41: =J27*Z5 -> 5440 | K41: =K27*Z5 -> 5080 | L41: =L27*Z5 -> 4960 | M41: =SUM(J41:L41) -> 15480 | N41: =N27*Z5 -> 4688 | O41: =O27*Z5 -> 4336 | P41: =P27*Z5 -> 4000 | Q41: =SUM(N41:P41) -> 13024 | R41: =SUM(Q41+M41+I40+E40) -> 28504
A42: Decollete' | B42: 9000 | C42: 8250 | D42: 9000 | E42: =B42+C42+D42 -> 26250 | F42: =F28*Y6 -> 8700 | G42: =G28*Y6 -> 9150 | H42: =H28*Y6 -> 10095 | I42: =SUM(F42:H42) -> 27945 | J42: =J28*Z6 -> 9840 | K42: =K28*Z6 -> 9150 | L42: =L28*Z6 -> 8940 | M42: =SUM(J42:L42) -> 27930 | N42: =N28*Z6 -> 9000 | O42: =O28*Z6 -> 8610 | P42: =P28*Z6 -> 8070 | Q42: =SUM(N42:P42) -> 25680 | R42: =SUM(Q42+M42+I42+E42) -> 107805
...

Sheet BUDGET PRODUZIONE
A1: Budget della produzione | T1: Distinta base della produzione
A3: Piano integrato di produzione, vendita e scorte di prodotti finiti | T3: LUREX 1 | U3: Centri Produttivi | V3: centri produttivi
A4: LUREX 1 | B4: GEN. | C4: FEB. | D4: MAR. | E4: I TRIM | F4: APR. | G4: MAG. | H4: GIU. | I4: II TRIM | J4: LUG. | K4: AGO. | L4: SET. | M4: III TRIM | N4: OTT. | O4: NOV. | P4: DIC. | Q4: IV TRIM | R4: Riepilogo Annuale | V4: Centro 1-taglio | W4: Centro 2-aggiunteria | X4: Centro 3-Montaggio | Y4: Centro 4-rifinitura e confezionamento
T5: Linea classica Mocassino | U5: Tempo Uomo | V5: 0.08 | W5: 0.42 | X5: 0.08 | Y5: 0.12
A6: Rimanenze Iniziali | U6: Tempo Macchina | V6: 0.08 | W6: 0.42 | X6: 0.01 | Y6: 0.08
A7: Mocassino | B7: 1 | C7: =B17 -> 950 | D7: =C17 -> 1040 | E7: =SUM(B7:D7) -> 1991 | F7: =D17 -> 1075 | G7: =F17 -> 1170 | H7: =G17 -> 1864.5 | I7: =SUM(F7:H7) -> 4109.5 | J7: =H17 -> 1899 | K7: =J17 -> 1819.5 | L7: =K17 -> 1743 | M7: =SUM(J7:L7) -> 5461.5 | N7: =L17 -> 1626 | O7: =N17 -> 1459.5 | P7: =O17 -> 886 | Q7: =SUM(N7:P7) -> 3971.5 | R7: =SUM(E7+I7+M7+Q7) -> 15533.5 | U7: scarto | V7: 0.02 | W7: 0 | X7: 0 | Y7: 0
A8: Decollete' | B8: 1 | C8: =B18 -> 345 | D8: =C18 -> 390 | E8: =SUM(B8:D8) -> 736 | F8: =D18 -> 777 | G8: =F18 -> 1690 | H8: =G18 -> 1858 | I8: =SUM(F8:H8) -> 4325 | J8: =H18 -> 1890 | K8: =J18 -> 1820 | L8: =K18 -> 860 | M8: =SUM(J8:L8) -> 4570 | N8: =L18 -> 821 | O8: =N18 -> 382 | P8: =O18 -> 347 | Q8: =SUM(N8:P8) -> 1550 | R8: =SUM(E8+I8+M8+Q8) -> 11181 | U8: pelle | V8: 0.3 | W8: 0 | X8: 0 | Y8: 0
A9: All Star | B9: 1 | C9: =B19 -> 200 | D9: =C19 -> 250 | E9: =SUM(B9:D9) -> 451 | F9: =D19 -> 335 | G9: =F19 -> 193 | H9: =G19 -> 205 | I9: =SUM(F9:H9) -> 733 | J9: =H19 -> 195 | K9: =J19 -> 202.5 | L9: =K19 -> 190 | M9: =SUM(J9:L9) -> 587.5 | N9: =L19 -> 157.5 | O9: =N19 -> 144.5 | P9: =O19 -> 106 | Q9: =SUM(N9:P9) -> 408 | R9: =SUM(E9+I9+M9+Q9) -> 2179.5 | U9: filo | V9: 0 | W9: 8 | X9: 0 | Y9: 0
A10: Slip on in pelle | B10: 0 | C10: =B20 -> 32 | D10: =C20 -> 39 | E10: =SUM(B10:D10) -> 71 | F10: =D20 -> 53 | G10: =F20 -> 12.4 | H10: =G20 -> 198 | I10: =SUM(F10:H10) -> 263.4 | J10: =H20 -> 186 | K10: =J20 -> 192 | L10: =K20 -> 180 | M10: =SUM(J10:L10) -> 558 | N10: =L20 -> 100 | O10: =N20 -> 92 | P10: =O20 -> 50 | Q10: =SUM(N10:P10) -> 242 | R10: =SUM(E10+I10+M10+Q10) -> 1134.4 | U10: suole | V10: 0 | W10: 0 | X10: 1 | Y10: 0
A11: Vendite
A12: Mocassino | B12: ='BUDGET COMMERCIALE'!B5+'BUDGET COMMERCIALE'!B10 -> 9800 | C12: ='BUDGET COMMERCIALE'!C5+'BUDGET COMMERCIALE'!C10 -> 9500 | D12: ='BUDGET COMMERCIALE'!D5+'BUDGET COMMERCIALE'!D10 -> 10400 | E12: =SUM('BUDGET PRODUZIONE'!B12:D12) -> 29700 | F12: ='BUDGET COMMERCIALE'!F5+'BUDGET COMMERCIALE'!F10 -> 10750 | G12: ='BUDGET COMMERCIALE'!G5+'BUDGET COMMERCIALE'!G10 -> 11700 | H12: ='BUDGET COMMERCIALE'!H5+'BUDGET COMMERCIALE'!H10 -> 12430 | I12: =SUM(F12:H12) -> 34880 | J12: ='BUDGET COMMERCIALE'!J5+'BUDGET COMMERCIALE'!J10 -> 12660 | K12: ='BUDGET COMMERCIALE'!K5+'BUDGET COMMERCIALE'!K10 -> 12130 | L12: ='BUDGET COMMERCIALE'!L5+'BUDGET COMMERCIALE'!L10 -> 11620 | M12: =SUM(J12:L12) -> 36410 | N12: ='BUDGET COMMERCIALE'!N5+'BUDGET COMMERCIALE'!N10 -> 10840 | O12: ='BUDGET COMMERCIALE'!O5+'BUDGET COMMERCIALE'!O10 -> 9730 | P12: ='BUDGET COMMERCIALE'!P5+'BUDGET COMMERCIALE'!P10 -> 8860 | Q12: =SUM(N12:P12) -> 29430 | R12: =SUM(E12+I12+M12+Q12) -> 130420
A13: Decollete' | B13: ='BUDGET COMMERCIALE'!B6+'BUDGET COMMERCIALE'!B11 -> 7300 | C13: ='BUDGET COMMERCIALE'!C6+'BUDGET COMMERCIALE'!C11 -> 6900 | D13: ='BUDGET COMMERCIALE'!D6+'BUDGET COMMERCIALE'!D11 -> 7800 | E13: =SUM(B13:D13) -> 22000 | F13: ='BUDGET COMMERCIALE'!F6+'BUDGET COMMERCIALE'!F11 -> 7770 | G13: ='BUDGET COMMERCIALE'!G6+'BUDGET COMMERCIALE'!G11 -> 8450 | H13: ='BUDGET COMMERCIALE'!H6+'BUDGET COMMERCIALE'!H11 -> 9290 | I13: =SUM(F13:H13) -> 25510 | J13: ='BUDGET COMMERCIALE'!J6+'BUDGET COMMERCIALE'!J11 -> 9450 | K13: ='BUDGET COMMERCIALE'!K6+'BUDGET COMMERCIALE'!K11 -> 9100 | L13: ='BUDGET COMMERCIALE'!L6+'BUDGET COMMERCIALE'!L11 -> 8600 | M13: =SUM(J13:L13) -> 27150 | N13: ='BUDGET COMMERCIALE'!N6+'BUDGET COMMERCIALE'!N11 -> 8210 | O13: ='BUDGET COMMERCIALE'!O6+'BUDGET COMMERCIALE'!O11 -> 7640 | P13: ='BUDGET COMMERCIALE'!P6+'BUDGET COMMERCIALE'!P11 -> 6940 | Q13: =SUM(N13:P13) -> 22790 | R13: =SUM(E13+I13+M13+Q13) -> 97450 | T13: Linea classica decollete' | U13: Tempo Uomo | V13: 0.08 | W13: 0.33 | X13: 0.08 | Y13: 0.12
A14: All Star | B14: ='BUDGET COMMERCIALE'!B7 -> 2000 | C14: ='BUDGET COMMERCIALE'!C7 -> 2000 | D14: ='BUDGET COMMERCIALE'!D7 -> 2500 | E14: =SUM(B14:D14) -> 6500 | F14: ='BUDGET COMMERCIALE'!F7 -> 3350 | G14: ='BUDGET COMMERCIALE'!G7 -> 3860 | H14: ='BUDGET COMMERCIALE'!H7 -> 4100 | I14: =SUM(F14:H14) -> 11310 | J14: ='BUDGET COMMERCIALE'!J7 -> 3900 | K14: ='BUDGET COMMERCIALE'!K7 -> 4050 | L14: ='BUDGET COMMERCIALE'!L7 -> 3800 | M14: =SUM(J14:L14) -> 11750 | N14: ='BUDGET COMMERCIALE'!N7 -> 3150 | O14: ='BUDGET COMMERCIALE'!O7 -> 2890 | P14: ='BUDGET COMMERCIALE'!P7 -> 2120 | Q14: =SUM(N14:P14) -> 8160 | R14: =SUM(E14+I14+M14+Q14) -> 37720 | U14: Tempo Macchina | V14: 0.08 | W14: 0.33 | X14: 0.01 | Y14: 0.08
A15: Slip on in pelle | B15: ='BUDGET COMMERCIALE'!B8 -> 640 | C15: ='BUDGET COMMERCIALE'!C8 -> 640 | D15: ='BUDGET COMMERCIALE'!D8 -> 780 | E15: =SUM(B15:D15) -> 2060 | F15: ='BUDGET COMMERCIALE'!F8 -> 1060 | G15: ='BUDGET COMMERCIALE'!G8 -> 1240 | H15: ='BUDGET COMMERCIALE'!H8 -> 1320 | I15: =SUM(F15:H15) -> 3620 | J15: ='BUDGET COMMERCIALE'!J8 -> 1240 | K15: ='BUDGET COMMERCIALE'!K8 -> 1280 | L15: ='BUDGET COMMERCIALE'!L8 -> 1200 | M15: =SUM(J15:L15) -> 3720 | N15: ='BUDGET COMMERCIALE'!N8 -> 1000 | O15: ='BUDGET COMMERCIALE'!O8 -> 920 | P15: ='BUDGET COMMERCIALE'!P8 -> 1000 | Q15: =SUM(N15:P15) -> 2920 | R15: =SUM(E15+I15+M15+Q15) -> 12320 | U15: scarto | V15: 0.01 | W15: 0 | X15: 0 | Y15: 0
A16: Rimanenze Finali programmate | U16: pelle | V16: 0.25 | W16: 0 | X16: 0 | Y16: 0
A17: Mocassino | B17: =C12*0.1 -> 950 | C17: =D12*0.1 -> 1040 | D17: =F12*0.1 -> 1075 | E17: =SUM(B17:D17) -> 3065 | F17: =G12*0.1 -> 1170 | G17: =H12*0.15 -> 1864.5 | H17: =J12*0.15 -> 1899 | I17: =SUM(F17:H17) -> 4933.5 | J17: =K12*0.15 -> 1819.5 | K17: =L12*0.15 -> 1743 | L17: =N12*0.15 -> 1626 | M17: =SUM(J17:L17) -> 5188.5 | N17: =O12*0.15 -> 1459.5 | O17: =P12*0.1 -> 886 | P17: =B12*0.1 -> 980 | Q17: =SUM(N17:P17) -> 3325.5 | R17: =SUM(E17+I17+M17+Q17) -> 16512.5 | U17: filo | V17: 0 | W17: 7 | X17: 0 | Y17: 0
A18: Decollete' | B18: =C13*0.05 -> 345 | C18: =D13*0.05 -> 390 | D18: =F13*0.1 -> 777 | E18: =SUM(B18:D18) -> 1512 | F18: =G13*0.2 -> 1690 | G18: =H13*0.2 -> 1858 | H18: =J13*0.2 -> 1890 | I18: =SUM(F18:H18) -> 5438 | J18: =K13*0.2 -> 1820 | K18: =L13*0.1 -> 860 | L18: =N13*0.1 -> 821 | M18: =SUM(J18:L18) -> 3501 | N18: =O13*0.05 -> 382 | O18: =P13*0.05 -> 347 | P18: =B13*0.05 -> 365 | Q18: =SUM(N18:P18) -> 1094 | R18: =SUM(E18+I18+M18+Q18) -> 11545 | U18: suole | V18: 0 | W18: 0 | X18: 1 | Y18: 0
A19: All Star | B19: =C14*0.1 -> 200 | C19: =D14*0.1 -> 250 | D19: =F14*0.1 -> 335 | E19: =SUM(B19:D19) -> 785 | F19: =G14*0.05 -> 193 | G19: =H14*0.05 -> 205 | H19: =J14*0.05 -> 195 | I19: =SUM(F19:H19) -> 593 | J19: =K14*0.05 -> 202.5 | K19: =L14*0.05 -> 190 | L19: =N14*0.05 -> 157.5 | M19: =SUM(J19:L19) -> 550 | N19: =O14*0.05 -> 144.5 | O19: =P14*0.05 -> 106 | P19: =B14*0.05 -> 100 | Q19: =SUM(N19:P19) -> 350.5 | R19: =SUM(E19+I19+M19+Q19) -> 2278.5
A20: Slip on in pelle | B20: =C15*0.05 -> 32 | C20: =D15*0.05 -> 39 | D20: =F15*0.05 -> 53 | E20: =SUM(B20:D20) -> 124 | F20: =G15*0.01 -> 12.4 | G20: =H15*0.15 -> 198 | H20: =J15*0.15 -> 186 | I20: =SUM(F20:H20) -> 396.4 | J20: =K15*0.15 -> 192 | K20: =L15*0.15 -> 180 | L20: =N15*0.1 -> 100 | M20: =SUM(J20:L20) -> 472 | N20: =O15*0.1 -> 92 | O20: =P15*0.05 -> 50 | P20: =B15*0.05 -> 32 | Q20: =SUM(N20:P20) -> 174 | R20: =SUM(E20+I20+M20+Q20) -> 1166.4
A21: Rimanenze Finali Effettive | T21: Linea sportiva All Star | U21: Tempo Uomo | V21: 0.08 | W21: 0.41 | X21: 0.05 | Y21: 0.12
A22: Mocassino | B22: =SUM(B17) -> 950 | C22: =SUM(C17) -> 1040 | D22: =SUM(D17) -> 1075 | E22: =SUM(E17) -> 3065 | F22: =SUM(F17) -> 1170 | G22: =SUM(G17) -> 1864.5 | H22: =SUM(H17) -> 1899 | I22: =SUM(I17) -> 4933.5 | ... R22: =SUM(R17) -> 16512.5 | U22: Tempo Macchina | V22: 0.08 | W22: 0.41 | X22: 0.01 | Y22: 0.08
A23: Decollete' | B23: =SUM(B18) -> 345 | C23: =SUM(C18) -> 390 | D23: =SUM(D18) -> 777 | E23: =SUM(E18) -> 1512 | F23: =SUM(F18) -> 1690 | G23: =SUM(G18) -> 1858 | H23: =SUM(H18) -> 1890 | I23: =SUM(I18) -> 5438 | ... R23: =SUM(R18) -> 11545 | U23: scarto | V23: 0.01 | W23: 0 | X23: 0 | Y23: 0
A24: All Star | B24: =SUM(B19) -> 200 | C24: =SUM(C19) -> 250 | D24: =SUM(D19) -> 335 | E24: =SUM(E19) -> 785 | F24: =SUM(F19) -> 193 | G24: =SUM(G19) -> 205 | H24: =SUM(H19) -> 195 | I24: =SUM(I19) -> 593 | ... R24: =SUM(R19) -> 2278.5 | U24: pelle | V24: 0.2 | W24: 0 | X24: 0 | Y24: 0
A25: Slip on in pelle | B25: =SUM(B20) -> 32 | C25: =SUM(C20) -> 39 | D25: =SUM(D20) -> 53 | E25: =SUM(E20) -> 124 | F25: =SUM(F20) -> 12.4 | G25: =SUM(G20) -> 198 | H25: =SUM(H20) -> 186 | I25: =SUM(I20) -> 396.4 | ... R25: =SUM(R20) -> 1166.4 | U25: Scatola | Y25: 1
A26: Produzione | U26: filo | V26: 0 | W26: 6 | X26: 0 | Y26: 0
A27: Mocassino | B27: =B12+B17-B7 -> 10749 | C27: =C12+C17-C7 -> 9590 | D27: =D12+D17-D7 -> 10435 | E27: =E12+E17-E7 -> 30774 | F27: =F12+F17-F7 -> 10845 | G27: =G12+G17-G7 -> 12394.5 | H27: =H12+H17-H7 -> 12464.5 | I27: =I12+I17-I7 -> 35704 | J27: 12580.5 | K27: 12053.5 | L27: 11503 | M27: 36137 | N27: 10673.5 | O27: 9156.5 | P27: 8954 | Q27: =SUM(N27:P27) -> 28784 | R27: =Q27+M27+I27+E27 -> 131399 | U27: suole | V27: 0 | W27: 0 | X27: 1 | Y27: 0
A28: Decollete' | B28: =B13+B18-B8 -> 7644 | C28: =C13+C18-C8 -> 6945 | D28: =D13+D18-D8 -> 8187 | E28: =E13+E18-E8 -> 22776 | F28: =F13+F18-F8 -> 8683 | G28: =G13+G18-G8 -> 8618 | H28: =H13+H18-H8 -> 9322 | I28: =I13+I18-I8 -> 26623 | J28: 3830 | K28: 8140 | L28: 8561 | M28: 20531 | N28: 7771 | O28: 7605 | P28: 6958 | Q28: =SUM(N28:P28) -> 22334 | R28: =Q28+M28+I28+E28 -> 92264
A29: All Star | B29: =B14+B19-B9 -> 2199 | C29: =C14+C19-C9 -> 2050 | D29: =D14+D19-D9 -> 2585 | E29: =E14+E19-E9 -> 6834 | F29: =F14+F19-F9 -> 3208 | G29: =G14+G19-G9 -> 3872 | H29: =H14+H19-H9 -> 4090 | I29: =I14+I19-I9 -> 11170 | J29: 3907.5 | K29: 4037.5 | L29: 3925 | M29: 11870 | N29: 3124 | O29: 2813 | P29: 2008 | Q29: =SUM(N29:P29) -> 7945 | R29: =Q29+M29+I29+E29 -> 37819
A30: Slip on in pelle | B30: =B15+B20-B10 -> 672 | C30: =C15+C20-C10 -> 647 | D30: =D15+D20-D10 -> 794 | E30: =E15+E20-E10 -> 2113 | F30: =F15+F20-F10 -> 1019.4 | G30: =G15+G20-G10 -> 1425.6 | H30: =H15+H20-H10 -> 1308 | I30: =I15+I20-I10 -> 3753 | J30: 623 | K30: 634 | L30: 560 | M30: =SUM(J30:L30) -> 1817 | N30: 496 | O30: 439 | P30: 491 | Q30: =SUM(N30:P30) -> 1426 | R30: =Q30+M30+I30+E30 -> 9109 | T30: Linea classica Slip on in pelle | U30: Tempo Uomo | V30: 0.08 | W30: 0.42 | X30: 0.08 | Y30: 0.12
U31: Tempo Macchina | V31: 0.08 | W31: 0.42 | X31: 0.01 | Y31: 0.08
U32: Scarto | V32: 0.02 | W32: 0 | X32: 0 | Y32: 0
U33: Pelle | V33: 0.25 | W33: 0 | X33: 0 | Y33: 0
U34: Filo | V34: 0 | W34: 7 | X34: 1 | Y34: 0
A35: Piano dei consumi di materie prime | U35: Suole | V35: 0 | W35: 0 | X35: 1 | Y35: 0
U36: Scatola(opzionale) | V36: 0 | W36: 0 | X36: 0 | Y36: 1
A37: LUREX | B37: GEN. | C37: FEB. | D37: MAR. | E37: I TRIM | F37: APR. | G37: MAG. | H37: GIU. | I37: II TRIM | J37: LUG. | K37: AGO. | L37: SET. | M37: III TRIM | N37: OTT. | O37: NOV. | P37: DIC. | Q37: IV TRIM | R37: Totale
A38: Scatola
A39: linea sportiva All Star | B39: =B29*$Y25 -> 2199 | C39: =C29*$Y25 -> 2050 | D39: =D29*$Y25 -> 2585 | E39: =SUM(B39:D39) -> 6834 | F39: =F29*$Y25 -> 3208 | G39: =G29*$Y25 -> 3872 | H39: =H29*$Y25 -> 4090 | I39: =H39+G39+F39 -> 11170 | J39: =J29*$Y25 -> 3907.5 | K39: =K29*$Y25 -> 4037.5 | L39: =L29*$Y25 -> 3925 | M39: =SUM(L39+K39+J39) -> 11870 | N39: =N29*$Y25 -> 3124 | O39: =O29*$Y25 -> 2813 | P39: =P29*$Y25 -> 2008 | Q39: =SUM(N39:P39) -> 7945 | R39: =Q39+M39+I39+E39 -> 37819
A40: linea classica slip on in pelle | B40: =B30*$Y36 -> 672 | C40: =C30*$Y36 -> 647 | D40: =D30*$Y36 -> 794 | E40: =SUM(B40:D40) -> 2113 | F40: =F30*$Y36 -> 1019.4 | G40: =G30*$Y36 -> 1425.6 | H40: =H30*$Y36 -> 1308 | I40: =SUM(F40:H40) -> 3753 | J40: =J30*$Y36 -> 623 | K40: =K30*$Y36 -> 634 | L40: =L30*$Y36 -> 560 | M40: =SUM(J40:L40) -> 1817 | N40: =N30*$Y36 -> 496 | O40: =O30*$Y36 -> 439 | P40: =P30*$Y36 -> 491 | Q40: =SUM(N40:P40) -> 1426 | R40: 6176
A41: Totale | B41: =SUM(B39:B40) -> 2871 | C41: =SUM(C39:C40) -> 2697 | D41: =SUM(D39:D40) -> 3379 | E41: =SUM(B41:D41) -> 8947 | F41: =SUM(F39:F40) -> 4227.4 | G41: =SUM(G39:G40) -> 5297.6 | H41: =SUM(H39:H40) -> 5398 | I41: =SUM(F41:H41) -> 14923 | J41: =SUM(J39:J40) -> 4530.5 | K41: =SUM(K39:K40) -> 4671.5 | L41: =SUM(L39:L40) -> 4485 | M41: =SUM(J41:L41) -> 13687 | N41: =SUM(N39:N40) -> 3620 | O41: =SUM(O39:O40) -> 3252 | P41: =SUM(P39:P40) -> 2499 | Q41: =Q39+Q40 -> 9371 | R41: =Q41+M41+I41+E41 -> 46928 | U41: Prezzo standard medio annuo
...

Sheet Foglio1
